<?xml version="1.0"?>

<robot name="ddbot">

    <!--<link name="base_link_dummy"/>-->

    <link name="base_link">
        <visual>
            <geometry>
                <!--<mesh filename="/home/arusso/catkin_ws/src/ddbot/ddbot_description/meshes/body.stl" scale="0.01 0.01 0.01"/>-->
                <box size="0.251 0.189 0.045"/>
            </geometry>
            <origin rpy="0 0 0" xyz="0.0375 0 0.009"/> <!-- 9 mm from ground -->
        </visual>
        <collision>
            <geometry>
                <box size="0.251 0.189 0.045"/>
            </geometry>
            <origin rpy="0 0 0" xyz="0.0375 0 0.009"/>
        </collision>
        <inertial>
            <mass value="0.9"/>
            <inertia ixx="0.002747" ixy="0.0" ixz="0.0" iyy="0.004793" iyz="0.0" izz="0.007404"/> <!-- height = 3cm -->
        </inertial>
    </link>

    <link name="left_wheel">
        <visual>
            <geometry>
                <cylinder length="0.016" radius="0.0254"/>
            </geometry>
            <origin rpy="1.57075 0 0" xyz="0 0 0"/>
        </visual>
        <collision>
            <geometry>
                <cylinder length="0.016" radius="0.0254"/>
            </geometry>
            <origin rpy="1.57075 0 0" xyz="0 0 0"/>
        </collision>
        <inertial>
            <mass value="0.075"/>
            <inertia ixx="0.0000137" ixy="0.0" ixz="0.0" iyy="0.00002419" iyz="0.0" izz="0.0000137"/> <!-- height = 3cm -->
        </inertial>
    </link>

    <link name="right_wheel">
        <visual>
            <geometry>
                <cylinder length="0.016" radius="0.0254"/>
            </geometry>
            <origin rpy="1.57075 0 0" xyz="0 0 0"/>
        </visual>
        <collision>
            <geometry>
                <cylinder length="0.016" radius="0.0254"/>
            </geometry>
            <origin rpy="1.57075 0 0" xyz="0 0 0"/>
        </collision>
        <inertial>
            <mass value="0.075"/>
            <inertia ixx="0.0000137" ixy="0.0" ixz="0.0" iyy="0.00002419" iyz="0.0" izz="0.0000137"/> <!-- height = 3cm -->
        </inertial>
    </link>


    <!--<joint name="dummy_joint" type="fixed">
        <parent link="base_link_dummy"/>
        <child link="base_link"/>
        <origin rpy="0 0 0" xyz="0 0 0"/>
    </joint>-->

    <joint name="wheel_left_joint" type="continuous">
        <parent link="base_link"/>
        <child link="left_wheel"/>
        <origin xyz="0 0.111 0"/>
        <axis xyz="0 1 0"/>
    </joint>

    <joint name="wheel_right_joint" type="continuous">
        <parent link="base_link"/>
        <child link="right_wheel"/>
        <origin xyz="0 -0.111 0"/>
        <axis xyz="0 1 0"/>
    </joint>





    <transmission name="left_wheel_trans">
      <type>transmission_interface/SimpleTransmission</type>
      <actuator name="left_wheel_motor">
        <mechanicalReduction>1</mechanicalReduction>
      </actuator>
      <joint name="wheel_left_joint">
        <hardwareInterface>hardware_interface/VelocityJointInterface</hardwareInterface>
      </joint>
    </transmission>
    
    <transmission name="right_wheel_trans">
      <type>transmission_interface/SimpleTransmission</type>
      <actuator name="right_wheel_motor">
        <mechanicalReduction>1</mechanicalReduction>
      </actuator>
      <joint name="wheel_right_joint">
        <hardwareInterface>hardware_interface/VelocityJointInterface</hardwareInterface>
      </joint>
    </transmission>




    <!-- Gazebo plugin for ROS Control -->
    <gazebo>
        <plugin name="gazebo_ros_control" filename="libgazebo_ros_control.so">
            <robotNamespace>/</robotNamespace>
        </plugin>
    </gazebo>

</robot>